[2024-04-11 01:42:38 +0000] [12060] [INFO] Starting gunicorn 21.2.0
[2024-04-11 01:42:38 +0000] [12060] [INFO] Listening at: http://0.0.0.0:5328 (12060)
[2024-04-11 01:42:38 +0000] [12060] [INFO] Using worker: sync
[2024-04-11 01:42:38 +0000] [12062] [INFO] Booting worker with pid: 12062
[2024-04-11 01:42:38 +0000] [12063] [INFO] Booting worker with pid: 12063
[2024-04-11 01:42:38 +0000] [12064] [INFO] Booting worker with pid: 12064
[2024-04-11 01:42:38 +0000] [12065] [INFO] Booting worker with pid: 12065
[2024-04-11 01:42:41 +0000] [12063] [ERROR] Exception in worker process
Traceback (most recent call last):
  File "/home/ubuntu/KNOWNET/venv/lib/python3.10/site-packages/gunicorn/arbiter.py", line 609, in spawn_worker
    worker.init_process()
  File "/home/ubuntu/KNOWNET/venv/lib/python3.10/site-packages/gunicorn/workers/base.py", line 134, in init_process
    self.load_wsgi()
  File "/home/ubuntu/KNOWNET/venv/lib/python3.10/site-packages/gunicorn/workers/base.py", line 146, in load_wsgi
    self.wsgi = self.app.wsgi()
  File "/home/ubuntu/KNOWNET/venv/lib/python3.10/site-packages/gunicorn/app/base.py", line 67, in wsgi
    self.callable = self.load()
  File "/home/ubuntu/KNOWNET/venv/lib/python3.10/site-packages/gunicorn/app/wsgiapp.py", line 58, in load
    return self.load_wsgiapp()
  File "/home/ubuntu/KNOWNET/venv/lib/python3.10/site-packages/gunicorn/app/wsgiapp.py", line 48, in load_wsgiapp
    return util.import_app(self.app_uri)
  File "/home/ubuntu/KNOWNET/venv/lib/python3.10/site-packages/gunicorn/util.py", line 371, in import_app
    mod = importlib.import_module(module)
  File "/usr/lib/python3.10/importlib/__init__.py", line 126, in import_module
    return _bootstrap._gcd_import(name[level:], package, level)
  File "<frozen importlib._bootstrap>", line 1050, in _gcd_import
  File "<frozen importlib._bootstrap>", line 1027, in _find_and_load
  File "<frozen importlib._bootstrap>", line 1006, in _find_and_load_unlocked
  File "<frozen importlib._bootstrap>", line 688, in _load_unlocked
  File "<frozen importlib._bootstrap_external>", line 883, in exec_module
  File "<frozen importlib._bootstrap>", line 241, in _call_with_frames_removed
  File "/home/ubuntu/KNOWNET/api/index.py", line 12, in <module>
    from embeddings_utils import get_embedding, get_embeddings
ModuleNotFoundError: No module named 'embeddings_utils'
[2024-04-11 01:42:41 +0000] [12065] [ERROR] Exception in worker process
Traceback (most recent call last):
  File "/home/ubuntu/KNOWNET/venv/lib/python3.10/site-packages/gunicorn/arbiter.py", line 609, in spawn_worker
    worker.init_process()
  File "/home/ubuntu/KNOWNET/venv/lib/python3.10/site-packages/gunicorn/workers/base.py", line 134, in init_process
    self.load_wsgi()
  File "/home/ubuntu/KNOWNET/venv/lib/python3.10/site-packages/gunicorn/workers/base.py", line 146, in load_wsgi
    self.wsgi = self.app.wsgi()
  File "/home/ubuntu/KNOWNET/venv/lib/python3.10/site-packages/gunicorn/app/base.py", line 67, in wsgi
    self.callable = self.load()
  File "/home/ubuntu/KNOWNET/venv/lib/python3.10/site-packages/gunicorn/app/wsgiapp.py", line 58, in load
    return self.load_wsgiapp()
  File "/home/ubuntu/KNOWNET/venv/lib/python3.10/site-packages/gunicorn/app/wsgiapp.py", line 48, in load_wsgiapp
    return util.import_app(self.app_uri)
  File "/home/ubuntu/KNOWNET/venv/lib/python3.10/site-packages/gunicorn/util.py", line 371, in import_app
    mod = importlib.import_module(module)
  File "/usr/lib/python3.10/importlib/__init__.py", line 126, in import_module
    return _bootstrap._gcd_import(name[level:], package, level)
  File "<frozen importlib._bootstrap>", line 1050, in _gcd_import
  File "<frozen importlib._bootstrap>", line 1027, in _find_and_load
  File "<frozen importlib._bootstrap>", line 1006, in _find_and_load_unlocked
  File "<frozen importlib._bootstrap>", line 688, in _load_unlocked
  File "<frozen importlib._bootstrap_external>", line 883, in exec_module
  File "<frozen importlib._bootstrap>", line 241, in _call_with_frames_removed
  File "/home/ubuntu/KNOWNET/api/index.py", line 12, in <module>
    from embeddings_utils import get_embedding, get_embeddings
ModuleNotFoundError: No module named 'embeddings_utils'
[2024-04-11 01:42:41 +0000] [12063] [INFO] Worker exiting (pid: 12063)
[2024-04-11 01:42:41 +0000] [12065] [INFO] Worker exiting (pid: 12065)
[2024-04-11 01:42:41 +0000] [12062] [ERROR] Exception in worker process
Traceback (most recent call last):
  File "/home/ubuntu/KNOWNET/venv/lib/python3.10/site-packages/gunicorn/arbiter.py", line 609, in spawn_worker
    worker.init_process()
  File "/home/ubuntu/KNOWNET/venv/lib/python3.10/site-packages/gunicorn/workers/base.py", line 134, in init_process
    self.load_wsgi()
  File "/home/ubuntu/KNOWNET/venv/lib/python3.10/site-packages/gunicorn/workers/base.py", line 146, in load_wsgi
    self.wsgi = self.app.wsgi()
  File "/home/ubuntu/KNOWNET/venv/lib/python3.10/site-packages/gunicorn/app/base.py", line 67, in wsgi
    self.callable = self.load()
  File "/home/ubuntu/KNOWNET/venv/lib/python3.10/site-packages/gunicorn/app/wsgiapp.py", line 58, in load
    return self.load_wsgiapp()
  File "/home/ubuntu/KNOWNET/venv/lib/python3.10/site-packages/gunicorn/app/wsgiapp.py", line 48, in load_wsgiapp
    return util.import_app(self.app_uri)
  File "/home/ubuntu/KNOWNET/venv/lib/python3.10/site-packages/gunicorn/util.py", line 371, in import_app
    mod = importlib.import_module(module)
  File "/usr/lib/python3.10/importlib/__init__.py", line 126, in import_module
    return _bootstrap._gcd_import(name[level:], package, level)
  File "<frozen importlib._bootstrap>", line 1050, in _gcd_import
  File "<frozen importlib._bootstrap>", line 1027, in _find_and_load
  File "<frozen importlib._bootstrap>", line 1006, in _find_and_load_unlocked
  File "<frozen importlib._bootstrap>", line 688, in _load_unlocked
  File "<frozen importlib._bootstrap_external>", line 883, in exec_module
  File "<frozen importlib._bootstrap>", line 241, in _call_with_frames_removed
  File "/home/ubuntu/KNOWNET/api/index.py", line 12, in <module>
    from embeddings_utils import get_embedding, get_embeddings
ModuleNotFoundError: No module named 'embeddings_utils'
[2024-04-11 01:42:41 +0000] [12062] [INFO] Worker exiting (pid: 12062)
[2024-04-11 01:42:41 +0000] [12064] [ERROR] Exception in worker process
Traceback (most recent call last):
  File "/home/ubuntu/KNOWNET/venv/lib/python3.10/site-packages/gunicorn/arbiter.py", line 609, in spawn_worker
    worker.init_process()
  File "/home/ubuntu/KNOWNET/venv/lib/python3.10/site-packages/gunicorn/workers/base.py", line 134, in init_process
    self.load_wsgi()
  File "/home/ubuntu/KNOWNET/venv/lib/python3.10/site-packages/gunicorn/workers/base.py", line 146, in load_wsgi
    self.wsgi = self.app.wsgi()
  File "/home/ubuntu/KNOWNET/venv/lib/python3.10/site-packages/gunicorn/app/base.py", line 67, in wsgi
    self.callable = self.load()
  File "/home/ubuntu/KNOWNET/venv/lib/python3.10/site-packages/gunicorn/app/wsgiapp.py", line 58, in load
    return self.load_wsgiapp()
  File "/home/ubuntu/KNOWNET/venv/lib/python3.10/site-packages/gunicorn/app/wsgiapp.py", line 48, in load_wsgiapp
    return util.import_app(self.app_uri)
  File "/home/ubuntu/KNOWNET/venv/lib/python3.10/site-packages/gunicorn/util.py", line 371, in import_app
    mod = importlib.import_module(module)
  File "/usr/lib/python3.10/importlib/__init__.py", line 126, in import_module
    return _bootstrap._gcd_import(name[level:], package, level)
  File "<frozen importlib._bootstrap>", line 1050, in _gcd_import
  File "<frozen importlib._bootstrap>", line 1027, in _find_and_load
  File "<frozen importlib._bootstrap>", line 1006, in _find_and_load_unlocked
  File "<frozen importlib._bootstrap>", line 688, in _load_unlocked
  File "<frozen importlib._bootstrap_external>", line 883, in exec_module
  File "<frozen importlib._bootstrap>", line 241, in _call_with_frames_removed
  File "/home/ubuntu/KNOWNET/api/index.py", line 12, in <module>
    from embeddings_utils import get_embedding, get_embeddings
ModuleNotFoundError: No module named 'embeddings_utils'
[2024-04-11 01:42:41 +0000] [12064] [INFO] Worker exiting (pid: 12064)
[2024-04-11 01:42:42 +0000] [12060] [ERROR] Worker (pid:12062) exited with code 3
[2024-04-11 01:42:42 +0000] [12060] [ERROR] Worker (pid:12063) exited with code 3
Traceback (most recent call last):
  File "/home/ubuntu/KNOWNET/venv/lib/python3.10/site-packages/gunicorn/arbiter.py", line 209, in run
    self.sleep()
  File "/home/ubuntu/KNOWNET/venv/lib/python3.10/site-packages/gunicorn/arbiter.py", line 360, in sleep
    ready = select.select([self.PIPE[0]], [], [], 1.0)
  File "/home/ubuntu/KNOWNET/venv/lib/python3.10/site-packages/gunicorn/arbiter.py", line 242, in handle_chld
    self.reap_workers()
  File "/home/ubuntu/KNOWNET/venv/lib/python3.10/site-packages/gunicorn/arbiter.py", line 530, in reap_workers
    raise HaltServer(reason, self.WORKER_BOOT_ERROR)
gunicorn.errors.HaltServer: <HaltServer 'Worker failed to boot.' 3>

During handling of the above exception, another exception occurred:

Traceback (most recent call last):
  File "/home/ubuntu/KNOWNET/venv/bin/gunicorn", line 8, in <module>
    sys.exit(run())
  File "/home/ubuntu/KNOWNET/venv/lib/python3.10/site-packages/gunicorn/app/wsgiapp.py", line 67, in run
    WSGIApplication("%(prog)s [OPTIONS] [APP_MODULE]").run()
  File "/home/ubuntu/KNOWNET/venv/lib/python3.10/site-packages/gunicorn/app/base.py", line 236, in run
    super().run()
  File "/home/ubuntu/KNOWNET/venv/lib/python3.10/site-packages/gunicorn/app/base.py", line 72, in run
    Arbiter(self).run()
  File "/home/ubuntu/KNOWNET/venv/lib/python3.10/site-packages/gunicorn/arbiter.py", line 229, in run
    self.halt(reason=inst.reason, exit_status=inst.exit_status)
  File "/home/ubuntu/KNOWNET/venv/lib/python3.10/site-packages/gunicorn/arbiter.py", line 342, in halt
    self.stop()
  File "/home/ubuntu/KNOWNET/venv/lib/python3.10/site-packages/gunicorn/arbiter.py", line 396, in stop
    time.sleep(0.1)
  File "/home/ubuntu/KNOWNET/venv/lib/python3.10/site-packages/gunicorn/arbiter.py", line 242, in handle_chld
    self.reap_workers()
  File "/home/ubuntu/KNOWNET/venv/lib/python3.10/site-packages/gunicorn/arbiter.py", line 530, in reap_workers
    raise HaltServer(reason, self.WORKER_BOOT_ERROR)
gunicorn.errors.HaltServer: <HaltServer 'Worker failed to boot.' 3>
